package com.infinityraider.agricraft.world;

import com.infinityraider.agricraft.api.v1.misc.IAgriConnectable;
import com.infinityraider.agricraft.api.v1.plant.IAgriPlant;
import com.infinityraider.agricraft.init.AgriBlocks;
import com.infinityraider.agricraft.tiles.irrigation.TileEntityChannel;
import com.infinityraider.agricraft.tiles.irrigation.TileEntityTank;
import com.infinityraider.infinitylib.utility.WorldHelper;
import net.minecraft.block.BlockFarmland;
import net.minecraft.block.BlockLog;
import net.minecraft.block.BlockStairs;
import net.minecraft.block.state.IBlockState;
import net.minecraft.init.Blocks;
import net.minecraft.item.ItemStack;
import net.minecraft.util.EnumFacing;
import net.minecraft.util.math.BlockPos;
import net.minecraft.world.World;
import net.minecraft.world.gen.structure.StructureBoundingBox;
import net.minecraft.world.gen.structure.StructureComponent;
import net.minecraft.world.gen.structure.StructureVillagePieces;

import java.util.List;
import java.util.Random;

import static net.minecraft.block.BlockLog.LOG_AXIS;

public class StructureGreenHouseIrrigated extends StructureGreenHouse {

    // Structure dimensions
    private static final int xSize = 17;
    private static final int ySize = 10;
    private static final int zSize = 16;

    private int averageGroundLevel = -1;

    public StructureGreenHouseIrrigated(StructureVillagePieces.Start villagePiece, int type, Random rand, StructureBoundingBox structureBoundingBox, EnumFacing facing) {
        super(villagePiece, type, rand, structureBoundingBox, facing);
    }

    public static StructureGreenHouse buildComponent(StructureVillagePieces.Start villagePiece, List<StructureComponent> pieces, Random random, int p1, int p2, int p3, EnumFacing facing, int p5) {
        StructureBoundingBox sbb = StructureBoundingBox.getComponentToAddBoundingBox(
                p1, p2, p3, 0, 0, 0, xSize, ySize, zSize, facing
        );
        return canVillageGoDeeper(sbb) && StructureComponent.findIntersecting(pieces, sbb) == null
                ? new StructureGreenHouseIrrigated(villagePiece, p5, random, sbb, facing)
                : null;
    }

    @Override
    public boolean addComponentParts(World world, Random rand, StructureBoundingBox boundingBox) {

        // Level off ground
        if(this.averageGroundLevel < 0) {
            this.averageGroundLevel = getAverageGroundLevel(world, boundingBox);
            if(this.averageGroundLevel < 0) {
                return true;
            }
            this.boundingBox.offset(0, this.averageGroundLevel - this.boundingBox.maxY + 7, 0);
        }

        // Cobblestone base
        IBlockState cobblestone = Blocks.COBBLESTONE.getDefaultState();
        this.fillWithBlocks(world, boundingBox, 0, 0, 0, xSize - 1, 0, zSize - 1, cobblestone, cobblestone, false);   //args: (world, boundingBox, minX, minY, MinZ, maxX, maxY, maxZ, placeBlock, replaceBlock, doReplace)

        // Ring of gravel
        IBlockState gravel = Blocks.GRAVEL.getDefaultState();
        this.fillWithBlocks(world, boundingBox, 0, 1, 0, xSize - 1, 1, 0, gravel, gravel, false);
        this.fillWithBlocks(world, boundingBox, 0, 1, 0, 0, 1, zSize - 1, gravel, gravel, false);
        this.fillWithBlocks(world, boundingBox, 0, 1, zSize - 1, xSize - 1, 1, zSize - 1, gravel, gravel, false);
        this.fillWithBlocks(world, boundingBox, xSize - 1, 1, 0, xSize - 1, 1, zSize - 1, gravel, gravel, false);

        // Grass patch
        IBlockState grass = Blocks.GRASS.getDefaultState();
        this.fillWithBlocks(world, boundingBox, 1, 1, 1, 9, 1, 5, grass, grass, false);
        this.fillWithBlocks(world, boundingBox, 10, 1, 1, 13, 1, 2, grass, grass, false);
        this.fillWithBlocks(world, boundingBox, 14, 1, 1, 15, 1, 5, grass, grass, false);

        // Cobblestone foundations
        this.fillWithBlocks(world, boundingBox, 1, 1, 6, 1, 1, 9, cobblestone, cobblestone, false);
        this.fillWithBlocks(world, boundingBox, 1, 1, 11, 1, 1, 14, cobblestone, cobblestone, false);
        this.fillWithBlocks(world, boundingBox, 15, 1, 6, 15, 1, 9, cobblestone, cobblestone, false);
        this.fillWithBlocks(world, boundingBox, 15, 1, 11, 15, 1, 14, cobblestone, cobblestone, false);
        this.setBlockState(world, cobblestone, 2, 1, 6, boundingBox);
        this.setBlockState(world, cobblestone, 8, 1, 6, boundingBox);
        this.setBlockState(world, cobblestone, 14, 1, 6, boundingBox);
        this.setBlockState(world, cobblestone, 2, 1, 14, boundingBox);
        this.setBlockState(world, cobblestone, 8, 1, 14, boundingBox);
        this.setBlockState(world, cobblestone, 14, 1, 14, boundingBox);
        this.fillWithBlocks(world, boundingBox, 10, 1, 3, 10, 1, 5, cobblestone, cobblestone, false);
        this.fillWithBlocks(world, boundingBox, 13, 1, 3, 13, 1, 5, cobblestone, cobblestone, false);
        this.fillWithBlocks(world, boundingBox, 11, 1, 3, 12, 1, 3, cobblestone, cobblestone, false);

        // Place slabs
        IBlockState stoneSlab = Blocks.DOUBLE_STONE_SLAB.getDefaultState();
        this.setBlockState(world, stoneSlab, 1, 1, 10, boundingBox);
        this.setBlockState(world, stoneSlab, 15, 1, 10, boundingBox);
        this.fillWithBlocks(world, boundingBox, 2, 1, 7, 2, 1, 13, stoneSlab, stoneSlab, false);
        this.fillWithBlocks(world, boundingBox, 8, 1, 7, 8, 1, 13, stoneSlab, stoneSlab, false);
        this.fillWithBlocks(world, boundingBox, 14, 1, 7, 14, 1, 13, stoneSlab, stoneSlab, false);
        this.fillWithBlocks(world, boundingBox, 2, 1, 7, 14, 1, 7, stoneSlab, stoneSlab, false);
        this.fillWithBlocks(world, boundingBox, 2, 1, 13, 14, 1, 13, stoneSlab, stoneSlab, false);
        this.fillWithBlocks(world, boundingBox, 11, 1, 4, 12, 1, 6, stoneSlab, stoneSlab, false);

        // Place water
        IBlockState water = Blocks.WATER.getDefaultState();
        this.fillWithBlocks(world, boundingBox, 3, 1, 6, 7, 1, 6, water, water, false);
        this.fillWithBlocks(world, boundingBox, 9, 1, 6, 10, 1, 6, water, water, false);
        this.fillWithBlocks(world, boundingBox, 3, 1, 14, 7, 1, 14, water, water, false);
        this.fillWithBlocks(world, boundingBox, 9, 1, 14, 13, 1, 14, water, water, false);
        this.setBlockState(world, water, 13, 1, 6, boundingBox);

        // Place farmland
        IBlockState farmland = Blocks.FARMLAND.getDefaultState()
                .withProperty(BlockFarmland.MOISTURE, 7);
        this.fillWithBlocks(world, boundingBox, 3, 1, 8, 7, 1, 12, farmland, farmland, false);
        this.fillWithBlocks(world, boundingBox, 9, 1, 8, 13, 1, 12, farmland, farmland, false);

        // Place standing logs
        IBlockState log = Blocks.LOG.getDefaultState();
        this.fillWithBlocks(world, boundingBox, 10, 2, 3, 10, 5, 3, log, log, false);
        this.fillWithBlocks(world, boundingBox, 13, 2, 3, 13, 5, 3, log, log, false);
        this.fillWithBlocks(world, boundingBox, 1, 2, 6, 1, 6, 6, log, log, false);
        this.fillWithBlocks(world, boundingBox, 3, 2, 6, 3, 5, 6, log, log, false);
        this.fillWithBlocks(world, boundingBox, 6, 2, 6, 6, 5, 6, log, log, false);
        this.fillWithBlocks(world, boundingBox, 8, 2, 6, 8, 6, 6, log, log, false);
        this.fillWithBlocks(world, boundingBox, 10, 2, 6, 10, 5, 6, log, log, false);
        this.fillWithBlocks(world, boundingBox, 13, 2, 6, 13, 5, 6, log, log, false);
        this.fillWithBlocks(world, boundingBox, 15, 2, 6, 15, 6, 6, log, log, false);
        this.fillWithBlocks(world, boundingBox, 1, 2, 9, 1, 5, 9, log, log, false);
        this.fillWithBlocks(world, boundingBox, 15, 2, 9, 15, 5, 9, log, log, false);
        this.fillWithBlocks(world, boundingBox, 1, 2, 11, 1, 5, 11, log, log, false);
        this.fillWithBlocks(world, boundingBox, 15, 2, 11, 15, 5, 11, log, log, false);
        this.fillWithBlocks(world, boundingBox, 1, 2, 14, 1, 6, 14, log, log, false);
        this.fillWithBlocks(world, boundingBox, 8, 2, 14, 8, 6, 14, log, log, false);
        this.fillWithBlocks(world, boundingBox, 15, 2, 14, 15, 6, 14, log, log, false);

        // Logs along x-axis
        this.fillWithBlocks(world, boundingBox, 11, 5, 3, 12, 5, 3, log.withProperty(LOG_AXIS, BlockLog.EnumAxis.X), log.withProperty(LOG_AXIS, BlockLog.EnumAxis.X), false);
        this.fillWithBlocks(world, boundingBox, 2, 6, 6, 7, 6, 6, log.withProperty(LOG_AXIS, BlockLog.EnumAxis.X), log.withProperty(LOG_AXIS, BlockLog.EnumAxis.X), false);
        this.fillWithBlocks(world, boundingBox, 9, 6, 6, 14, 6, 6, log.withProperty(LOG_AXIS, BlockLog.EnumAxis.X), log.withProperty(LOG_AXIS, BlockLog.EnumAxis.X), false);
        this.fillWithBlocks(world, boundingBox, 4, 4, 6, 5, 4, 6, log.withProperty(LOG_AXIS, BlockLog.EnumAxis.X), log.withProperty(LOG_AXIS, BlockLog.EnumAxis.X), false);
        this.fillWithBlocks(world, boundingBox, 11, 4, 6, 12, 4, 6, log.withProperty(LOG_AXIS, BlockLog.EnumAxis.X), log.withProperty(LOG_AXIS, BlockLog.EnumAxis.X), false);
        this.fillWithBlocks(world, boundingBox, 2, 6, 14, 7, 6, 14, log.withProperty(LOG_AXIS, BlockLog.EnumAxis.X), log.withProperty(LOG_AXIS, BlockLog.EnumAxis.X), false);
        this.fillWithBlocks(world, boundingBox, 9, 6, 14, 14, 6, 14, log.withProperty(LOG_AXIS, BlockLog.EnumAxis.X), log.withProperty(LOG_AXIS, BlockLog.EnumAxis.X), false);
        // Logs along z-axis
        this.fillWithBlocks(world, boundingBox, 1, 6, 7, 1, 6, 13, log.withProperty(LOG_AXIS, BlockLog.EnumAxis.Z), log.withProperty(LOG_AXIS, BlockLog.EnumAxis.Z), false);
        this.fillWithBlocks(world, boundingBox, 8, 6, 7, 8, 6, 13, log.withProperty(LOG_AXIS, BlockLog.EnumAxis.Z), log.withProperty(LOG_AXIS, BlockLog.EnumAxis.Z), false);
        this.fillWithBlocks(world, boundingBox, 15, 6, 7, 15, 6, 13, log.withProperty(LOG_AXIS, BlockLog.EnumAxis.Z), log.withProperty(LOG_AXIS, BlockLog.EnumAxis.Z), false);
        this.fillWithBlocks(world, boundingBox, 10, 5, 4, 10, 5, 5, log.withProperty(LOG_AXIS, BlockLog.EnumAxis.Z), log.withProperty(LOG_AXIS, BlockLog.EnumAxis.Z), false);
        this.fillWithBlocks(world, boundingBox, 13, 5, 4, 13, 5, 5, log.withProperty(LOG_AXIS, BlockLog.EnumAxis.Z), log.withProperty(LOG_AXIS, BlockLog.EnumAxis.Z), false);
        this.setBlockState(world, log.withProperty(LOG_AXIS, BlockLog.EnumAxis.Z), 1, 4, 10, boundingBox);
        this.setBlockState(world, log.withProperty(LOG_AXIS, BlockLog.EnumAxis.Z), 15, 4, 10, boundingBox);

        // Cobblestone walls
        this.fillWithBlocks(world, boundingBox, 4, 2, 6, 5, 2, 6, cobblestone, cobblestone, false);
        this.fillWithBlocks(world, boundingBox, 10, 2, 4, 10, 2, 5, cobblestone, cobblestone, false);
        this.fillWithBlocks(world, boundingBox, 11, 2, 3, 12, 2, 3, cobblestone, cobblestone, false);
        this.fillWithBlocks(world, boundingBox, 13, 2, 4, 13, 2, 5, cobblestone, cobblestone, false);
        this.fillWithBlocks(world, boundingBox, 1, 2, 7, 1, 2, 8, cobblestone, cobblestone, false);
        this.fillWithBlocks(world, boundingBox, 1, 2, 12, 1, 2, 13, cobblestone, cobblestone, false);
        this.fillWithBlocks(world, boundingBox, 15, 2, 7, 15, 2, 8, cobblestone, cobblestone, false);
        this.fillWithBlocks(world, boundingBox, 15, 2, 12, 15, 2, 13, cobblestone, cobblestone, false);
        this.fillWithBlocks(world, boundingBox, 2, 2, 14, 7, 2, 14, cobblestone, cobblestone, false);
        this.fillWithBlocks(world, boundingBox, 9, 2, 14, 14, 2, 14, cobblestone, cobblestone, false);
        this.setBlockState(world, cobblestone, 2, 2, 6, boundingBox);
        this.setBlockState(world, cobblestone, 7, 2, 6, boundingBox);
        this.setBlockState(world, cobblestone, 9, 2, 6, boundingBox);
        this.setBlockState(world, cobblestone, 14, 2, 6, boundingBox);

        // Place glass
        IBlockState glass = Blocks.GLASS.getDefaultState();
        this.fillWithBlocks(world, boundingBox, 1, 3, 7, 1, 5, 8, glass, glass, false);
        this.fillWithBlocks(world, boundingBox, 1, 3, 12, 1, 5, 13, glass, glass, false);
        this.fillWithBlocks(world, boundingBox, 2, 3, 6, 2, 5, 6, glass, glass, false);
        this.fillWithBlocks(world, boundingBox, 4, 3, 6, 5, 3, 6, glass, glass, false);
        this.fillWithBlocks(world, boundingBox, 7, 3, 6, 7, 5, 6, glass, glass, false);
        this.fillWithBlocks(world, boundingBox, 9, 3, 6, 9, 5, 6, glass, glass, false);
        this.fillWithBlocks(world, boundingBox, 14, 3, 6, 14, 5, 6, glass, glass, false);
        this.fillWithBlocks(world, boundingBox, 11, 5, 4, 12, 5, 6, glass, glass, false);
        this.fillWithBlocks(world, boundingBox, 15, 3, 7, 15, 5, 8, glass, glass, false);
        this.fillWithBlocks(world, boundingBox, 15, 3, 12, 15, 5, 13, glass, glass, false);
        this.fillWithBlocks(world, boundingBox, 2, 3, 14, 7, 5, 14, glass, glass, false);
        this.fillWithBlocks(world, boundingBox, 9, 3, 14, 14, 5, 14, glass, glass, false);
        this.fillWithBlocks(world, boundingBox, 2, 6, 7, 7, 6, 13, glass, glass, false);
        this.fillWithBlocks(world, boundingBox, 9, 6, 7, 14, 6, 13, glass, glass, false);
        this.setBlockState(world, glass, 4, 5, 6, boundingBox);
        this.setBlockState(world, glass, 1, 5, 10, boundingBox);
        this.setBlockState(world, glass, 15, 5, 10, boundingBox);

        // Wooden pillars
        IBlockState planks = Blocks.PLANKS.getDefaultState();
        this.fillWithBlocks(world, boundingBox, 3, 2, 1, 3, 4, 1, planks, planks, false);
        this.fillWithBlocks(world, boundingBox, 3, 2, 4, 3, 4, 4, planks, planks, false);
        this.fillWithBlocks(world, boundingBox, 6, 2, 1, 6, 4, 1, planks, planks, false);
        this.fillWithBlocks(world, boundingBox, 6, 2, 4, 6, 4, 4, planks, planks, false);

        // Oak stairs - Tank
        IBlockState stairs = Blocks.OAK_STAIRS.getDefaultState()
                .withProperty(BlockStairs.HALF, BlockStairs.EnumHalf.TOP);

        this.setBlockState(world, stairs.withProperty(BlockStairs.FACING, EnumFacing.NORTH), 3, 4, 3, boundingBox);
        this.setBlockState(world, stairs.withProperty(BlockStairs.FACING, EnumFacing.NORTH), 6, 4, 3, boundingBox);

        this.setBlockState(world, stairs.withProperty(BlockStairs.FACING, EnumFacing.EAST), 5, 4, 1, boundingBox);
        this.setBlockState(world, stairs.withProperty(BlockStairs.FACING, EnumFacing.EAST), 5, 4, 4, boundingBox);

        this.setBlockState(world, stairs.withProperty(BlockStairs.FACING, EnumFacing.WEST), 4, 4, 1, boundingBox);
        this.setBlockState(world, stairs.withProperty(BlockStairs.FACING, EnumFacing.WEST), 4, 4, 4, boundingBox);

        this.setBlockState(world, stairs.withProperty(BlockStairs.FACING, EnumFacing.SOUTH), 3, 4, 2, boundingBox);
        this.setBlockState(world, stairs.withProperty(BlockStairs.FACING, EnumFacing.SOUTH), 6, 4, 2, boundingBox);

        // Oak stairs - Seed analyzer
        this.setBlockState(world, stairs.withProperty(BlockStairs.FACING, EnumFacing.SOUTH), 11, 4, 3, boundingBox);
        this.setBlockState(world, stairs.withProperty(BlockStairs.FACING, EnumFacing.SOUTH), 12, 4, 3, boundingBox);

        this.setBlockState(world, stairs.withProperty(BlockStairs.FACING, EnumFacing.WEST), 10, 4, 4, boundingBox);
        this.setBlockState(world, stairs.withProperty(BlockStairs.FACING, EnumFacing.WEST), 10, 4, 5, boundingBox);

        this.setBlockState(world, stairs.withProperty(BlockStairs.FACING, EnumFacing.EAST), 13, 4, 4, boundingBox);
        this.setBlockState(world, stairs.withProperty(BlockStairs.FACING, EnumFacing.EAST), 13, 4, 5, boundingBox);

        // Place doors
        this.generateDoor(world, boundingBox, rand, 1, 2, 10, EnumFacing.EAST, Blocks.OAK_DOOR);
        this.generateDoor(world, boundingBox, rand, 15, 2, 10, EnumFacing.WEST, Blocks.OAK_DOOR);

        // Fill with air
        this.fillWithAir(world, boundingBox, 0, 2, 0, 0, 9, 15);
        this.fillWithAir(world, boundingBox, 16, 2, 0, 16, 9, 15);
        this.fillWithAir(world, boundingBox, 0, 2, 0, 16, 9, 0);
        this.fillWithAir(world, boundingBox, 0, 2, 15, 16, 9, 15);
        this.fillWithAir(world, boundingBox, 2, 2, 7, 14, 5, 13);
        this.fillWithAir(world, boundingBox, 1, 7, 6, 14, 9, 14);
        this.fillWithAir(world, boundingBox, 1, 3, 7, 2, 9, 5);
        this.fillWithAir(world, boundingBox, 2, 2, 7, 2, 2, 5);
        this.fillWithAir(world, boundingBox, 3, 2, 2, 3, 3, 3);
        this.fillWithAir(world, boundingBox, 2, 2, 5, 9, 4, 5);
        this.fillWithAir(world, boundingBox, 2, 5, 5, 4, 5, 5);
        this.fillWithAir(world, boundingBox, 6, 5, 5, 9, 5, 5);
        this.fillWithAir(world, boundingBox, 2, 6, 5, 9, 9, 5);
        this.fillWithAir(world, boundingBox, 4, 3, 1, 5, 3, 1);
        this.fillWithAir(world, boundingBox, 4, 2, 4, 5, 3, 4);
        this.fillWithAir(world, boundingBox, 4, 2, 2, 5, 4, 3);
        this.fillWithAir(world, boundingBox, 6, 2, 2, 6, 3, 3);
        this.fillWithAir(world, boundingBox, 7, 2, 2, 9, 9, 4);
        this.fillWithAir(world, boundingBox, 10, 2, 2, 13, 9, 2);
        this.fillWithAir(world, boundingBox, 10, 6, 3, 13, 9, 5);
        this.fillWithAir(world, boundingBox, 14, 2, 2, 14, 9, 5);
        this.fillWithAir(world, boundingBox, 7, 3, 1, 15, 9, 1);
        this.fillWithAir(world, boundingBox, 15, 3, 2, 15, 9, 5);
        this.fillWithAir(world, boundingBox, 11, 3, 4, 12, 4, 5);
        this.fillWithAir(world, boundingBox, 11, 2, 6, 12, 4, 6);
        this.fillWithAir(world, boundingBox, 11, 2, 5, 12, 4, 5);
        this.fillWithAir(world, boundingBox, 12, 2, 4, 12, 4, 4);

        // Place fences
        IBlockState fence = Blocks.OAK_FENCE.getDefaultState();
        this.fillWithBlocks(world, boundingBox, 1, 2, 1, 2, 2, 1, fence, fence, false);
        this.fillWithBlocks(world, boundingBox, 4, 2, 1, 5, 2, 1, fence, fence, false);
        this.fillWithBlocks(world, boundingBox, 7, 2, 1, 15, 2, 1, fence, fence, false);
        this.fillWithBlocks(world, boundingBox, 1, 2, 2, 1, 2, 5, fence, fence, false);
        this.fillWithBlocks(world, boundingBox, 15, 2, 2, 15, 2, 5, fence, fence, false);
        this.fillWithBlocks(world, boundingBox, 8, 4, 9, 8, 4, 11, fence, fence, false);
        this.setBlockState(world, fence, 8, 5, 9, boundingBox);
        this.setBlockState(world, fence, 8, 5, 11, boundingBox);

        // Place torches
        this.placeTorch(world, EnumFacing.WEST, 0, 4, 6, boundingBox);
        this.placeTorch(world, EnumFacing.WEST, 0, 4, 9, boundingBox);
        this.placeTorch(world, EnumFacing.WEST, 0, 4, 11, boundingBox);
        this.placeTorch(world, EnumFacing.WEST, 0, 4, 14, boundingBox);
        this.placeTorch(world, EnumFacing.WEST, 9, 4, 3, boundingBox);
        this.placeTorch(world, EnumFacing.WEST, 14, 4, 9, boundingBox);
        this.placeTorch(world, EnumFacing.WEST, 14, 4, 11, boundingBox);

        this.placeTorch(world, EnumFacing.UP, 1, 3, 1, boundingBox);
        this.placeTorch(world, EnumFacing.UP, 15, 3, 1, boundingBox);

        this.placeTorch(world, EnumFacing.SOUTH, 1, 4, 5, boundingBox);
        this.placeTorch(world, EnumFacing.SOUTH, 8, 4, 5, boundingBox);

        this.placeTorch(world, EnumFacing.SOUTH, 10, 4, 2, boundingBox);
        this.placeTorch(world, EnumFacing.SOUTH, 13, 4, 2, boundingBox);
        this.placeTorch(world, EnumFacing.SOUTH, 15, 4, 5, boundingBox);

        this.placeTorch(world, EnumFacing.EAST, 14, 4, 3, boundingBox);
        this.placeTorch(world, EnumFacing.EAST, 16, 4, 6, boundingBox);
        this.placeTorch(world, EnumFacing.EAST, 16, 4, 9, boundingBox);
        this.placeTorch(world, EnumFacing.EAST, 16, 4, 14, boundingBox);
        this.placeTorch(world, EnumFacing.EAST, 16, 4, 14, boundingBox);
        this.placeTorch(world, EnumFacing.EAST, 2, 4, 9, boundingBox);
        this.placeTorch(world, EnumFacing.EAST, 2, 4, 11, boundingBox);

        // Place crops
        Random random = new Random();
        List<IAgriPlant> plants = this.getPlantPool();

        for(int x = 3; x <= 7; x++) {
            for(int z = 8; z <= 12; z++) {
                this.generateStructureCrop(world, boundingBox, x, 2, z, (z % 2 == 1 && x % 2 == 0) || (x == 5 && z == 10), random, plants);
            }
        }
        for(int x = 9; x <= 13; x++) {
            for(int z = 8; z <= 12; z++) {
                this.generateStructureCrop(world, boundingBox, x, 2, z, (z % 2 == 1 && x % 2 == 0) || (x == 11 && z == 10), random, plants);
            }
        }

        // Place water tank
        for(int x = 3; x <= 6; x++) {
            for(int y = 5; y <= 8; y++) {
                for(int z = 1; z <= 4; z++) {
                    this.generateStructureWoodenTank(world, boundingBox, x, y, z);
                }
            }
        }

        // Place irrigation channels
        this.fillWithBlocks(world, boundingBox, 5, 5, 5, 5, 5, 10, AgriBlocks.getInstance().CHANNEL.getDefaultState(), AgriBlocks.getInstance().CHANNEL.getDefaultState(), false);
        for(int z = 5; z <= 10; z++) {
            this.generateStructureIrrigationChannel(world, boundingBox, 5, 5, z);
        }
        this.fillWithBlocks(world, boundingBox, 6, 5, 10, 11, 5, 10, AgriBlocks.getInstance().CHANNEL.getDefaultState(), AgriBlocks.getInstance().CHANNEL.getDefaultState(), false);
        for(int x = 6; x <= 11; x++) {
            this.generateStructureIrrigationChannel(world, boundingBox, x, 5, 10);
        }

        // Place sprinklers
        this.generateStructureSprinkler(world, boundingBox, 5, 4, 10);
        this.generateStructureSprinkler(world, boundingBox, 11, 4, 10);

        // Place seed analyzer
        this.generateStructureSeedAnalyzer(world, boundingBox, 11, 2, 4, EnumFacing.SOUTH);

        return true;
    }

    protected void generateStructureWoodenTank(World world, StructureBoundingBox boundingBox, int x, int y, int z) {

        int xCoord = this.getXWithOffset(x, z);
        int yCoord = this.getYWithOffset(y);
        int zCoord = this.getZWithOffset(x, z);

        BlockPos pos = new BlockPos(xCoord, yCoord, zCoord);

        if(!boundingBox.isVecInside(pos)) {
            return;
        }

        world.setBlockState(pos, AgriBlocks.getInstance().TANK.getDefaultState());
        TileEntityTank tank = (TileEntityTank) world.getTileEntity(pos);

        if(tank == null) {
            tank = new TileEntityTank();
            world.setTileEntity(pos, tank);
        }

        tank.setMaterial(new ItemStack(Blocks.PLANKS, 1, 0));

        WorldHelper.getTile(world, pos, IAgriConnectable.class)
                .ifPresent(IAgriConnectable::refreshConnections);

        WorldHelper.getTileNeighbors(world, pos, IAgriConnectable.class)
                .forEach(IAgriConnectable::refreshConnections);

    }

    protected void generateStructureIrrigationChannel(World world, StructureBoundingBox boundingBox, int x, int y, int z) {

        int xCoord = this.getXWithOffset(x, z);
        int yCoord = this.getYWithOffset(y);
        int zCoord = this.getZWithOffset(x, z);

        BlockPos pos = new BlockPos(xCoord, yCoord, zCoord);

        if(!boundingBox.isVecInside(pos)) {
            return;
        }

        world.setBlockState(pos, AgriBlocks.getInstance().CHANNEL.getDefaultState());
        TileEntityChannel channel = (TileEntityChannel) world.getTileEntity(pos);

        if(channel == null) {
            return;
        }

        channel.setMaterial(new ItemStack(Blocks.PLANKS, 1, 0));

        WorldHelper.getTile(world, pos, IAgriConnectable.class)
                .ifPresent(IAgriConnectable::refreshConnections);

        WorldHelper.getTileNeighbors(world, pos, IAgriConnectable.class)
                .forEach(IAgriConnectable::refreshConnections);

    }

    protected void generateStructureSprinkler(World world, StructureBoundingBox boundingBox, int x, int y, int z) {

        int xCoord = this.getXWithOffset(x, z);
        int yCoord = this.getYWithOffset(y);
        int zCoord = this.getZWithOffset(x, z);

        BlockPos pos = new BlockPos(xCoord, yCoord, zCoord);

        if(!boundingBox.isVecInside(pos)) {
            return;
        }

        world.setBlockState(pos, AgriBlocks.getInstance().SPRINKLER.getDefaultState());

        WorldHelper.getTile(world, pos.up(), IAgriConnectable.class)
                .ifPresent(IAgriConnectable::refreshConnections);

    }

}
